2018-12-11 21:05:30,652 ERROR [10] CommonHelpers.Helpers.LogError - API Error: 
System.InvalidOperationException: A circular reference was detected while serializing an object of type 'System.Data.Entity.DynamicProxies.Event_3A455CD93C34B8BE2C9D8FF4A5E451E6079A90D28736001EA06B2B7973320596'.
   at System.Web.Script.Serialization.JavaScriptSerializer.SerializeValueInternal(Object o, StringBuilder sb, Int32 depth, Hashtable objectsInUse, SerializationFormat serializationFormat, MemberInfo currentMember)
   at System.Web.Script.Serialization.JavaScriptSerializer.SerializeValue(Object o, StringBuilder sb, Int32 depth, Hashtable objectsInUse, SerializationFormat serializationFormat, MemberInfo currentMember)
   at System.Web.Script.Serialization.JavaScriptSerializer.SerializeCustomObject(Object o, StringBuilder sb, Int32 depth, Hashtable objectsInUse, SerializationFormat serializationFormat)
   at System.Web.Script.Serialization.JavaScriptSerializer.SerializeValueInternal(Object o, StringBuilder sb, Int32 depth, Hashtable objectsInUse, SerializationFormat serializationFormat, MemberInfo currentMember)
   at System.Web.Script.Serialization.JavaScriptSerializer.SerializeValue(Object o, StringBuilder sb, Int32 depth, Hashtable objectsInUse, SerializationFormat serializationFormat, MemberInfo currentMember)
   at System.Web.Script.Serialization.JavaScriptSerializer.SerializeEnumerable(IEnumerable enumerable, StringBuilder sb, Int32 depth, Hashtable objectsInUse, SerializationFormat serializationFormat)
   at System.Web.Script.Serialization.JavaScriptSerializer.SerializeValueInternal(Object o, StringBuilder sb, Int32 depth, Hashtable objectsInUse, SerializationFormat serializationFormat, MemberInfo currentMember)
   at System.Web.Script.Serialization.JavaScriptSerializer.SerializeValue(Object o, StringBuilder sb, Int32 depth, Hashtable objectsInUse, SerializationFormat serializationFormat, MemberInfo currentMember)
   at System.Web.Script.Serialization.JavaScriptSerializer.SerializeCustomObject(Object o, StringBuilder sb, Int32 depth, Hashtable objectsInUse, SerializationFormat serializationFormat)
   at System.Web.Script.Serialization.JavaScriptSerializer.SerializeValueInternal(Object o, StringBuilder sb, Int32 depth, Hashtable objectsInUse, SerializationFormat serializationFormat, MemberInfo currentMember)
   at System.Web.Script.Serialization.JavaScriptSerializer.SerializeValue(Object o, StringBuilder sb, Int32 depth, Hashtable objectsInUse, SerializationFormat serializationFormat, MemberInfo currentMember)
   at System.Web.Script.Serialization.JavaScriptSerializer.SerializeEnumerable(IEnumerable enumerable, StringBuilder sb, Int32 depth, Hashtable objectsInUse, SerializationFormat serializationFormat)
   at System.Web.Script.Serialization.JavaScriptSerializer.SerializeValueInternal(Object o, StringBuilder sb, Int32 depth, Hashtable objectsInUse, SerializationFormat serializationFormat, MemberInfo currentMember)
   at System.Web.Script.Serialization.JavaScriptSerializer.SerializeValue(Object o, StringBuilder sb, Int32 depth, Hashtable objectsInUse, SerializationFormat serializationFormat, MemberInfo currentMember)
   at System.Web.Script.Serialization.JavaScriptSerializer.SerializeCustomObject(Object o, StringBuilder sb, Int32 depth, Hashtable objectsInUse, SerializationFormat serializationFormat)
   at System.Web.Script.Serialization.JavaScriptSerializer.SerializeValueInternal(Object o, StringBuilder sb, Int32 depth, Hashtable objectsInUse, SerializationFormat serializationFormat, MemberInfo currentMember)
   at System.Web.Script.Serialization.JavaScriptSerializer.SerializeValue(Object o, StringBuilder sb, Int32 depth, Hashtable objectsInUse, SerializationFormat serializationFormat, MemberInfo currentMember)
   at System.Web.Script.Serialization.JavaScriptSerializer.Serialize(Object obj, StringBuilder output, SerializationFormat serializationFormat)
   at System.Web.Script.Serialization.JavaScriptSerializer.Serialize(Object obj, SerializationFormat serializationFormat)
   at System.Web.Mvc.JsonResult.ExecuteResult(ControllerContext context)
   at System.Web.Mvc.ControllerActionInvoker.InvokeActionResultFilterRecursive(IList`1 filters, Int32 filterIndex, ResultExecutingContext preContext, ControllerContext controllerContext, ActionResult actionResult)
   at System.Web.Mvc.ControllerActionInvoker.InvokeActionResultFilterRecursive(IList`1 filters, Int32 filterIndex, ResultExecutingContext preContext, ControllerContext controllerContext, ActionResult actionResult)
   at System.Web.Mvc.ControllerActionInvoker.InvokeActionResultWithFilters(ControllerContext controllerContext, IList`1 filters, ActionResult actionResult)
   at System.Web.Mvc.Async.AsyncControllerActionInvoker.<>c__DisplayClass21.<BeginInvokeAction>b__1e(IAsyncResult asyncResult)
2018-12-12 18:32:54,299 ERROR [67] CommonHelpers.Helpers.LogError - Speaker Error
System.Data.Entity.Infrastructure.DbUpdateException: An error occurred while updating the entries. See the inner exception for details. ---> System.Data.Entity.Core.UpdateException: An error occurred while updating the entries. See the inner exception for details. ---> System.Data.SqlClient.SqlException: The INSERT statement conflicted with the FOREIGN KEY constraint "FK_EventIDD". The conflict occurred in database "Event_Management2", table "dbo.Event", column 'ID'.
The statement has been terminated.
   at System.Data.SqlClient.SqlConnection.OnError(SqlException exception, Boolean breakConnection, Action`1 wrapCloseInAction)
   at System.Data.SqlClient.TdsParser.ThrowExceptionAndWarning(TdsParserStateObject stateObj, Boolean callerHasConnectionLock, Boolean asyncClose)
   at System.Data.SqlClient.TdsParser.TryRun(RunBehavior runBehavior, SqlCommand cmdHandler, SqlDataReader dataStream, BulkCopySimpleResultSet bulkCopyHandler, TdsParserStateObject stateObj, Boolean& dataReady)
   at System.Data.SqlClient.SqlCommand.FinishExecuteReader(SqlDataReader ds, RunBehavior runBehavior, String resetOptionsString, Boolean isInternal, Boolean forDescribeParameterEncryption, Boolean shouldCacheForAlwaysEncrypted)
   at System.Data.SqlClient.SqlCommand.CompleteAsyncExecuteReader(Boolean isInternal, Boolean forDescribeParameterEncryption)
   at System.Data.SqlClient.SqlCommand.InternalEndExecuteNonQuery(IAsyncResult asyncResult, String endMethod, Boolean isInternal)
   at System.Data.SqlClient.SqlCommand.EndExecuteNonQueryInternal(IAsyncResult asyncResult)
   at System.Data.SqlClient.SqlCommand.EndExecuteNonQueryAsync(IAsyncResult asyncResult)
   at System.Threading.Tasks.TaskFactory`1.FromAsyncCoreLogic(IAsyncResult iar, Func`2 endFunction, Action`1 endAction, Task`1 promise, Boolean requiresSynchronization)
--- End of stack trace from previous location where exception was thrown ---
   at System.Runtime.ExceptionServices.ExceptionDispatchInfo.Throw()
   at System.Runtime.CompilerServices.TaskAwaiter.HandleNonSuccessAndDebuggerNotification(Task task)
   at System.Data.Entity.Core.Mapping.Update.Internal.DynamicUpdateCommand.<ExecuteAsync>d__0.MoveNext()
--- End of stack trace from previous location where exception was thrown ---
   at System.Runtime.ExceptionServices.ExceptionDispatchInfo.Throw()
   at System.Runtime.CompilerServices.TaskAwaiter.HandleNonSuccessAndDebuggerNotification(Task task)
   at System.Data.Entity.Core.Mapping.Update.Internal.UpdateTranslator.<UpdateAsync>d__0.MoveNext()
   --- End of inner exception stack trace ---
   at System.Data.Entity.Core.Mapping.Update.Internal.UpdateTranslator.<UpdateAsync>d__0.MoveNext()
--- End of stack trace from previous location where exception was thrown ---
   at System.Runtime.ExceptionServices.ExceptionDispatchInfo.Throw()
   at System.Runtime.CompilerServices.TaskAwaiter.HandleNonSuccessAndDebuggerNotification(Task task)
   at System.Data.Entity.Core.Objects.ObjectContext.<ExecuteInTransactionAsync>d__3d`1.MoveNext()
--- End of stack trace from previous location where exception was thrown ---
   at System.Runtime.ExceptionServices.ExceptionDispatchInfo.Throw()
   at System.Runtime.CompilerServices.TaskAwaiter.HandleNonSuccessAndDebuggerNotification(Task task)
   at System.Data.Entity.Core.Objects.ObjectContext.<SaveChangesToStoreAsync>d__39.MoveNext()
--- End of stack trace from previous location where exception was thrown ---
   at System.Runtime.ExceptionServices.ExceptionDispatchInfo.Throw()
   at System.Runtime.CompilerServices.TaskAwaiter.HandleNonSuccessAndDebuggerNotification(Task task)
   at System.Data.Entity.SqlServer.DefaultSqlExecutionStrategy.<ExecuteAsyncImplementation>d__9`1.MoveNext()
--- End of stack trace from previous location where exception was thrown ---
   at System.Runtime.ExceptionServices.ExceptionDispatchInfo.Throw()
   at System.Runtime.CompilerServices.TaskAwaiter.HandleNonSuccessAndDebuggerNotification(Task task)
   at System.Data.Entity.Core.Objects.ObjectContext.<SaveChangesInternalAsync>d__31.MoveNext()
   --- End of inner exception stack trace ---
   at System.Runtime.ExceptionServices.ExceptionDispatchInfo.Throw()
   at System.Runtime.CompilerServices.TaskAwaiter.HandleNonSuccessAndDebuggerNotification(Task task)
   at System.Runtime.CompilerServices.TaskAwaiter`1.GetResult()
   at EventManagement.BusinessLogic.Business.Speakers.<AddUpdateSpeakers_>d__3.MoveNext() in D:\Techxcape Projects\Galactic\CMS\EventManagementPortal\EventManagement.BusinessLogic\Business\Speakers.cs:line 85
--- End of stack trace from previous location where exception was thrown ---
   at System.Runtime.ExceptionServices.ExceptionDispatchInfo.Throw()
   at System.Runtime.CompilerServices.TaskAwaiter.HandleNonSuccessAndDebuggerNotification(Task task)
   at System.Runtime.CompilerServices.TaskAwaiter`1.GetResult()
   at EventManagement.Controllers.SpeakersController.<Create>d__5.MoveNext() in D:\Techxcape Projects\Galactic\CMS\EventManagementPortal\EventManagement\Controllers\SpeakersController.cs:line 70
2018-12-12 18:33:53,477 ERROR [90] CommonHelpers.Helpers.LogError - Speaker Error
System.Data.Entity.Infrastructure.DbUpdateException: An error occurred while updating the entries. See the inner exception for details. ---> System.Data.Entity.Core.UpdateException: An error occurred while updating the entries. See the inner exception for details. ---> System.Data.SqlClient.SqlException: The INSERT statement conflicted with the FOREIGN KEY constraint "FK_EventIDD". The conflict occurred in database "Event_Management2", table "dbo.Event", column 'ID'.
The statement has been terminated.
   at System.Data.SqlClient.SqlConnection.OnError(SqlException exception, Boolean breakConnection, Action`1 wrapCloseInAction)
   at System.Data.SqlClient.TdsParser.ThrowExceptionAndWarning(TdsParserStateObject stateObj, Boolean callerHasConnectionLock, Boolean asyncClose)
   at System.Data.SqlClient.TdsParser.TryRun(RunBehavior runBehavior, SqlCommand cmdHandler, SqlDataReader dataStream, BulkCopySimpleResultSet bulkCopyHandler, TdsParserStateObject stateObj, Boolean& dataReady)
   at System.Data.SqlClient.SqlCommand.FinishExecuteReader(SqlDataReader ds, RunBehavior runBehavior, String resetOptionsString, Boolean isInternal, Boolean forDescribeParameterEncryption, Boolean shouldCacheForAlwaysEncrypted)
   at System.Data.SqlClient.SqlCommand.CompleteAsyncExecuteReader(Boolean isInternal, Boolean forDescribeParameterEncryption)
   at System.Data.SqlClient.SqlCommand.InternalEndExecuteNonQuery(IAsyncResult asyncResult, String endMethod, Boolean isInternal)
   at System.Data.SqlClient.SqlCommand.EndExecuteNonQueryInternal(IAsyncResult asyncResult)
   at System.Data.SqlClient.SqlCommand.EndExecuteNonQueryAsync(IAsyncResult asyncResult)
   at System.Threading.Tasks.TaskFactory`1.FromAsyncCoreLogic(IAsyncResult iar, Func`2 endFunction, Action`1 endAction, Task`1 promise, Boolean requiresSynchronization)
--- End of stack trace from previous location where exception was thrown ---
   at System.Runtime.ExceptionServices.ExceptionDispatchInfo.Throw()
   at System.Runtime.CompilerServices.TaskAwaiter.HandleNonSuccessAndDebuggerNotification(Task task)
   at System.Data.Entity.Core.Mapping.Update.Internal.DynamicUpdateCommand.<ExecuteAsync>d__0.MoveNext()
--- End of stack trace from previous location where exception was thrown ---
   at System.Runtime.ExceptionServices.ExceptionDispatchInfo.Throw()
   at System.Runtime.CompilerServices.TaskAwaiter.HandleNonSuccessAndDebuggerNotification(Task task)
   at System.Data.Entity.Core.Mapping.Update.Internal.UpdateTranslator.<UpdateAsync>d__0.MoveNext()
   --- End of inner exception stack trace ---
   at System.Data.Entity.Core.Mapping.Update.Internal.UpdateTranslator.<UpdateAsync>d__0.MoveNext()
--- End of stack trace from previous location where exception was thrown ---
   at System.Runtime.ExceptionServices.ExceptionDispatchInfo.Throw()
   at System.Runtime.CompilerServices.TaskAwaiter.HandleNonSuccessAndDebuggerNotification(Task task)
   at System.Data.Entity.Core.Objects.ObjectContext.<ExecuteInTransactionAsync>d__3d`1.MoveNext()
--- End of stack trace from previous location where exception was thrown ---
   at System.Runtime.ExceptionServices.ExceptionDispatchInfo.Throw()
   at System.Runtime.CompilerServices.TaskAwaiter.HandleNonSuccessAndDebuggerNotification(Task task)
   at System.Data.Entity.Core.Objects.ObjectContext.<SaveChangesToStoreAsync>d__39.MoveNext()
--- End of stack trace from previous location where exception was thrown ---
   at System.Runtime.ExceptionServices.ExceptionDispatchInfo.Throw()
   at System.Runtime.CompilerServices.TaskAwaiter.HandleNonSuccessAndDebuggerNotification(Task task)
   at System.Data.Entity.SqlServer.DefaultSqlExecutionStrategy.<ExecuteAsyncImplementation>d__9`1.MoveNext()
--- End of stack trace from previous location where exception was thrown ---
   at System.Runtime.ExceptionServices.ExceptionDispatchInfo.Throw()
   at System.Runtime.CompilerServices.TaskAwaiter.HandleNonSuccessAndDebuggerNotification(Task task)
   at System.Data.Entity.Core.Objects.ObjectContext.<SaveChangesInternalAsync>d__31.MoveNext()
   --- End of inner exception stack trace ---
   at System.Runtime.ExceptionServices.ExceptionDispatchInfo.Throw()
   at System.Runtime.CompilerServices.TaskAwaiter.HandleNonSuccessAndDebuggerNotification(Task task)
   at System.Runtime.CompilerServices.TaskAwaiter`1.GetResult()
   at EventManagement.BusinessLogic.Business.Speakers.<AddUpdateSpeakers_>d__3.MoveNext() in D:\Techxcape Projects\Galactic\CMS\EventManagementPortal\EventManagement.BusinessLogic\Business\Speakers.cs:line 85
--- End of stack trace from previous location where exception was thrown ---
   at System.Runtime.ExceptionServices.ExceptionDispatchInfo.Throw()
   at System.Runtime.CompilerServices.TaskAwaiter.HandleNonSuccessAndDebuggerNotification(Task task)
   at System.Runtime.CompilerServices.TaskAwaiter`1.GetResult()
   at EventManagement.Controllers.SpeakersController.<Create>d__5.MoveNext() in D:\Techxcape Projects\Galactic\CMS\EventManagementPortal\EventManagement\Controllers\SpeakersController.cs:line 70
2018-12-12 18:34:16,772 ERROR [97] CommonHelpers.Helpers.LogError - Speaker Error
System.Data.Entity.Infrastructure.DbUpdateException: An error occurred while updating the entries. See the inner exception for details. ---> System.Data.Entity.Core.UpdateException: An error occurred while updating the entries. See the inner exception for details. ---> System.Data.SqlClient.SqlException: The INSERT statement conflicted with the FOREIGN KEY constraint "FK_EventIDD". The conflict occurred in database "Event_Management2", table "dbo.Event", column 'ID'.
The statement has been terminated.
   at System.Data.SqlClient.SqlConnection.OnError(SqlException exception, Boolean breakConnection, Action`1 wrapCloseInAction)
   at System.Data.SqlClient.TdsParser.ThrowExceptionAndWarning(TdsParserStateObject stateObj, Boolean callerHasConnectionLock, Boolean asyncClose)
   at System.Data.SqlClient.TdsParser.TryRun(RunBehavior runBehavior, SqlCommand cmdHandler, SqlDataReader dataStream, BulkCopySimpleResultSet bulkCopyHandler, TdsParserStateObject stateObj, Boolean& dataReady)
   at System.Data.SqlClient.SqlCommand.FinishExecuteReader(SqlDataReader ds, RunBehavior runBehavior, String resetOptionsString, Boolean isInternal, Boolean forDescribeParameterEncryption, Boolean shouldCacheForAlwaysEncrypted)
   at System.Data.SqlClient.SqlCommand.CompleteAsyncExecuteReader(Boolean isInternal, Boolean forDescribeParameterEncryption)
   at System.Data.SqlClient.SqlCommand.InternalEndExecuteNonQuery(IAsyncResult asyncResult, String endMethod, Boolean isInternal)
   at System.Data.SqlClient.SqlCommand.EndExecuteNonQueryInternal(IAsyncResult asyncResult)
   at System.Data.SqlClient.SqlCommand.EndExecuteNonQueryAsync(IAsyncResult asyncResult)
   at System.Threading.Tasks.TaskFactory`1.FromAsyncCoreLogic(IAsyncResult iar, Func`2 endFunction, Action`1 endAction, Task`1 promise, Boolean requiresSynchronization)
--- End of stack trace from previous location where exception was thrown ---
   at System.Runtime.ExceptionServices.ExceptionDispatchInfo.Throw()
   at System.Runtime.CompilerServices.TaskAwaiter.HandleNonSuccessAndDebuggerNotification(Task task)
   at System.Data.Entity.Core.Mapping.Update.Internal.DynamicUpdateCommand.<ExecuteAsync>d__0.MoveNext()
--- End of stack trace from previous location where exception was thrown ---
   at System.Runtime.ExceptionServices.ExceptionDispatchInfo.Throw()
   at System.Runtime.CompilerServices.TaskAwaiter.HandleNonSuccessAndDebuggerNotification(Task task)
   at System.Data.Entity.Core.Mapping.Update.Internal.UpdateTranslator.<UpdateAsync>d__0.MoveNext()
   --- End of inner exception stack trace ---
   at System.Data.Entity.Core.Mapping.Update.Internal.UpdateTranslator.<UpdateAsync>d__0.MoveNext()
--- End of stack trace from previous location where exception was thrown ---
   at System.Runtime.ExceptionServices.ExceptionDispatchInfo.Throw()
   at System.Runtime.CompilerServices.TaskAwaiter.HandleNonSuccessAndDebuggerNotification(Task task)
   at System.Data.Entity.Core.Objects.ObjectContext.<ExecuteInTransactionAsync>d__3d`1.MoveNext()
--- End of stack trace from previous location where exception was thrown ---
   at System.Runtime.ExceptionServices.ExceptionDispatchInfo.Throw()
   at System.Runtime.CompilerServices.TaskAwaiter.HandleNonSuccessAndDebuggerNotification(Task task)
   at System.Data.Entity.Core.Objects.ObjectContext.<SaveChangesToStoreAsync>d__39.MoveNext()
--- End of stack trace from previous location where exception was thrown ---
   at System.Runtime.ExceptionServices.ExceptionDispatchInfo.Throw()
   at System.Runtime.CompilerServices.TaskAwaiter.HandleNonSuccessAndDebuggerNotification(Task task)
   at System.Data.Entity.SqlServer.DefaultSqlExecutionStrategy.<ExecuteAsyncImplementation>d__9`1.MoveNext()
--- End of stack trace from previous location where exception was thrown ---
   at System.Runtime.ExceptionServices.ExceptionDispatchInfo.Throw()
   at System.Runtime.CompilerServices.TaskAwaiter.HandleNonSuccessAndDebuggerNotification(Task task)
   at System.Data.Entity.Core.Objects.ObjectContext.<SaveChangesInternalAsync>d__31.MoveNext()
   --- End of inner exception stack trace ---
   at System.Runtime.ExceptionServices.ExceptionDispatchInfo.Throw()
   at System.Runtime.CompilerServices.TaskAwaiter.HandleNonSuccessAndDebuggerNotification(Task task)
   at System.Runtime.CompilerServices.TaskAwaiter`1.GetResult()
   at EventManagement.BusinessLogic.Business.Speakers.<AddUpdateSpeakers_>d__3.MoveNext() in D:\Techxcape Projects\Galactic\CMS\EventManagementPortal\EventManagement.BusinessLogic\Business\Speakers.cs:line 85
--- End of stack trace from previous location where exception was thrown ---
   at System.Runtime.ExceptionServices.ExceptionDispatchInfo.Throw()
   at System.Runtime.CompilerServices.TaskAwaiter.HandleNonSuccessAndDebuggerNotification(Task task)
   at System.Runtime.CompilerServices.TaskAwaiter`1.GetResult()
   at EventManagement.Controllers.SpeakersController.<Create>d__5.MoveNext() in D:\Techxcape Projects\Galactic\CMS\EventManagementPortal\EventManagement\Controllers\SpeakersController.cs:line 70
2018-12-12 18:56:23,074 ERROR [66] CommonHelpers.Helpers.LogError - Speaker Error
System.Data.Entity.Infrastructure.DbUpdateException: An error occurred while updating the entries. See the inner exception for details. ---> System.Data.Entity.Core.UpdateException: An error occurred while updating the entries. See the inner exception for details. ---> System.Data.SqlClient.SqlException: The INSERT statement conflicted with the FOREIGN KEY constraint "FK_EventIDD". The conflict occurred in database "Event_Management2", table "dbo.Event", column 'ID'.
The statement has been terminated.
   at System.Data.SqlClient.SqlCommand.<>c.<ExecuteDbDataReaderAsync>b__180_0(Task`1 result)
   at System.Threading.Tasks.ContinuationResultTaskFromResultTask`2.InnerInvoke()
   at System.Threading.Tasks.Task.Execute()
--- End of stack trace from previous location where exception was thrown ---
   at System.Runtime.ExceptionServices.ExceptionDispatchInfo.Throw()
   at System.Runtime.CompilerServices.TaskAwaiter.HandleNonSuccessAndDebuggerNotification(Task task)
   at System.Data.Entity.Core.Mapping.Update.Internal.DynamicUpdateCommand.<ExecuteAsync>d__0.MoveNext()
--- End of stack trace from previous location where exception was thrown ---
   at System.Runtime.ExceptionServices.ExceptionDispatchInfo.Throw()
   at System.Runtime.CompilerServices.TaskAwaiter.HandleNonSuccessAndDebuggerNotification(Task task)
   at System.Data.Entity.Core.Mapping.Update.Internal.UpdateTranslator.<UpdateAsync>d__0.MoveNext()
   --- End of inner exception stack trace ---
   at System.Data.Entity.Core.Mapping.Update.Internal.UpdateTranslator.<UpdateAsync>d__0.MoveNext()
--- End of stack trace from previous location where exception was thrown ---
   at System.Runtime.ExceptionServices.ExceptionDispatchInfo.Throw()
   at System.Runtime.CompilerServices.TaskAwaiter.HandleNonSuccessAndDebuggerNotification(Task task)
   at System.Data.Entity.Core.Objects.ObjectContext.<ExecuteInTransactionAsync>d__3d`1.MoveNext()
--- End of stack trace from previous location where exception was thrown ---
   at System.Runtime.ExceptionServices.ExceptionDispatchInfo.Throw()
   at System.Runtime.CompilerServices.TaskAwaiter.HandleNonSuccessAndDebuggerNotification(Task task)
   at System.Data.Entity.Core.Objects.ObjectContext.<SaveChangesToStoreAsync>d__39.MoveNext()
--- End of stack trace from previous location where exception was thrown ---
   at System.Runtime.ExceptionServices.ExceptionDispatchInfo.Throw()
   at System.Runtime.CompilerServices.TaskAwaiter.HandleNonSuccessAndDebuggerNotification(Task task)
   at System.Data.Entity.SqlServer.DefaultSqlExecutionStrategy.<ExecuteAsyncImplementation>d__9`1.MoveNext()
--- End of stack trace from previous location where exception was thrown ---
   at System.Runtime.ExceptionServices.ExceptionDispatchInfo.Throw()
   at System.Runtime.CompilerServices.TaskAwaiter.HandleNonSuccessAndDebuggerNotification(Task task)
   at System.Data.Entity.Core.Objects.ObjectContext.<SaveChangesInternalAsync>d__31.MoveNext()
   --- End of inner exception stack trace ---
   at System.Runtime.ExceptionServices.ExceptionDispatchInfo.Throw()
   at System.Runtime.CompilerServices.TaskAwaiter.HandleNonSuccessAndDebuggerNotification(Task task)
   at System.Runtime.CompilerServices.TaskAwaiter`1.GetResult()
   at EventManagement.BusinessLogic.Business.Speakers.<AddUpdateSpeakers_>d__3.MoveNext() in D:\Techxcape Projects\Galactic\CMS\EventManagementPortal\EventManagement.BusinessLogic\Business\Speakers.cs:line 85
--- End of stack trace from previous location where exception was thrown ---
   at System.Runtime.ExceptionServices.ExceptionDispatchInfo.Throw()
   at System.Runtime.CompilerServices.TaskAwaiter.HandleNonSuccessAndDebuggerNotification(Task task)
   at System.Runtime.CompilerServices.TaskAwaiter`1.GetResult()
   at EventManagement.Controllers.SpeakersController.<Create>d__5.MoveNext() in D:\Techxcape Projects\Galactic\CMS\EventManagementPortal\EventManagement\Controllers\SpeakersController.cs:line 70
2018-12-12 18:57:56,846 ERROR [66] CommonHelpers.Helpers.LogError - Speaker Error
System.Data.Entity.Infrastructure.DbUpdateException: An error occurred while updating the entries. See the inner exception for details. ---> System.Data.Entity.Core.UpdateException: An error occurred while updating the entries. See the inner exception for details. ---> System.Data.SqlClient.SqlException: The INSERT statement conflicted with the FOREIGN KEY constraint "FK_EventIDD". The conflict occurred in database "Event_Management2", table "dbo.Event", column 'ID'.
The statement has been terminated.
   at System.Data.SqlClient.SqlCommand.<>c.<ExecuteDbDataReaderAsync>b__180_0(Task`1 result)
   at System.Threading.Tasks.ContinuationResultTaskFromResultTask`2.InnerInvoke()
   at System.Threading.Tasks.Task.Execute()
--- End of stack trace from previous location where exception was thrown ---
   at System.Runtime.ExceptionServices.ExceptionDispatchInfo.Throw()
   at System.Runtime.CompilerServices.TaskAwaiter.HandleNonSuccessAndDebuggerNotification(Task task)
   at System.Data.Entity.Core.Mapping.Update.Internal.DynamicUpdateCommand.<ExecuteAsync>d__0.MoveNext()
--- End of stack trace from previous location where exception was thrown ---
   at System.Runtime.ExceptionServices.ExceptionDispatchInfo.Throw()
   at System.Runtime.CompilerServices.TaskAwaiter.HandleNonSuccessAndDebuggerNotification(Task task)
   at System.Data.Entity.Core.Mapping.Update.Internal.UpdateTranslator.<UpdateAsync>d__0.MoveNext()
   --- End of inner exception stack trace ---
   at System.Data.Entity.Core.Mapping.Update.Internal.UpdateTranslator.<UpdateAsync>d__0.MoveNext()
--- End of stack trace from previous location where exception was thrown ---
   at System.Runtime.ExceptionServices.ExceptionDispatchInfo.Throw()
   at System.Runtime.CompilerServices.TaskAwaiter.HandleNonSuccessAndDebuggerNotification(Task task)
   at System.Data.Entity.Core.Objects.ObjectContext.<ExecuteInTransactionAsync>d__3d`1.MoveNext()
--- End of stack trace from previous location where exception was thrown ---
   at System.Runtime.ExceptionServices.ExceptionDispatchInfo.Throw()
   at System.Runtime.CompilerServices.TaskAwaiter.HandleNonSuccessAndDebuggerNotification(Task task)
   at System.Data.Entity.Core.Objects.ObjectContext.<SaveChangesToStoreAsync>d__39.MoveNext()
--- End of stack trace from previous location where exception was thrown ---
   at System.Runtime.ExceptionServices.ExceptionDispatchInfo.Throw()
   at System.Runtime.CompilerServices.TaskAwaiter.HandleNonSuccessAndDebuggerNotification(Task task)
   at System.Data.Entity.SqlServer.DefaultSqlExecutionStrategy.<ExecuteAsyncImplementation>d__9`1.MoveNext()
--- End of stack trace from previous location where exception was thrown ---
   at System.Runtime.ExceptionServices.ExceptionDispatchInfo.Throw()
   at System.Runtime.CompilerServices.TaskAwaiter.HandleNonSuccessAndDebuggerNotification(Task task)
   at System.Data.Entity.Core.Objects.ObjectContext.<SaveChangesInternalAsync>d__31.MoveNext()
   --- End of inner exception stack trace ---
   at System.Runtime.ExceptionServices.ExceptionDispatchInfo.Throw()
   at System.Runtime.CompilerServices.TaskAwaiter.HandleNonSuccessAndDebuggerNotification(Task task)
   at System.Runtime.CompilerServices.TaskAwaiter`1.GetResult()
   at EventManagement.BusinessLogic.Business.Speakers.<AddUpdateSpeakers_>d__3.MoveNext() in D:\Techxcape Projects\Galactic\CMS\EventManagementPortal\EventManagement.BusinessLogic\Business\Speakers.cs:line 85
--- End of stack trace from previous location where exception was thrown ---
   at System.Runtime.ExceptionServices.ExceptionDispatchInfo.Throw()
   at System.Runtime.CompilerServices.TaskAwaiter.HandleNonSuccessAndDebuggerNotification(Task task)
   at System.Runtime.CompilerServices.TaskAwaiter`1.GetResult()
   at EventManagement.Controllers.SpeakersController.<Create>d__5.MoveNext() in D:\Techxcape Projects\Galactic\CMS\EventManagementPortal\EventManagement\Controllers\SpeakersController.cs:line 70
2018-12-12 18:59:40,944 ERROR [71] CommonHelpers.Helpers.LogError - Speaker Error
System.Data.Entity.Infrastructure.DbUpdateException: An error occurred while updating the entries. See the inner exception for details. ---> System.Data.Entity.Core.UpdateException: An error occurred while updating the entries. See the inner exception for details. ---> System.Data.SqlClient.SqlException: The INSERT statement conflicted with the FOREIGN KEY constraint "FK_EventIDD". The conflict occurred in database "Event_Management2", table "dbo.Event", column 'ID'.
The statement has been terminated.
   at System.Data.SqlClient.SqlCommand.<>c.<ExecuteDbDataReaderAsync>b__180_0(Task`1 result)
   at System.Threading.Tasks.ContinuationResultTaskFromResultTask`2.InnerInvoke()
   at System.Threading.Tasks.Task.Execute()
--- End of stack trace from previous location where exception was thrown ---
   at System.Runtime.ExceptionServices.ExceptionDispatchInfo.Throw()
   at System.Runtime.CompilerServices.TaskAwaiter.HandleNonSuccessAndDebuggerNotification(Task task)
   at System.Data.Entity.Core.Mapping.Update.Internal.DynamicUpdateCommand.<ExecuteAsync>d__0.MoveNext()
--- End of stack trace from previous location where exception was thrown ---
   at System.Runtime.ExceptionServices.ExceptionDispatchInfo.Throw()
   at System.Runtime.CompilerServices.TaskAwaiter.HandleNonSuccessAndDebuggerNotification(Task task)
   at System.Data.Entity.Core.Mapping.Update.Internal.UpdateTranslator.<UpdateAsync>d__0.MoveNext()
   --- End of inner exception stack trace ---
   at System.Data.Entity.Core.Mapping.Update.Internal.UpdateTranslator.<UpdateAsync>d__0.MoveNext()
--- End of stack trace from previous location where exception was thrown ---
   at System.Runtime.ExceptionServices.ExceptionDispatchInfo.Throw()
   at System.Runtime.CompilerServices.TaskAwaiter.HandleNonSuccessAndDebuggerNotification(Task task)
   at System.Data.Entity.Core.Objects.ObjectContext.<ExecuteInTransactionAsync>d__3d`1.MoveNext()
--- End of stack trace from previous location where exception was thrown ---
   at System.Runtime.ExceptionServices.ExceptionDispatchInfo.Throw()
   at System.Runtime.CompilerServices.TaskAwaiter.HandleNonSuccessAndDebuggerNotification(Task task)
   at System.Data.Entity.Core.Objects.ObjectContext.<SaveChangesToStoreAsync>d__39.MoveNext()
--- End of stack trace from previous location where exception was thrown ---
   at System.Runtime.ExceptionServices.ExceptionDispatchInfo.Throw()
   at System.Runtime.CompilerServices.TaskAwaiter.HandleNonSuccessAndDebuggerNotification(Task task)
   at System.Data.Entity.SqlServer.DefaultSqlExecutionStrategy.<ExecuteAsyncImplementation>d__9`1.MoveNext()
--- End of stack trace from previous location where exception was thrown ---
   at System.Runtime.ExceptionServices.ExceptionDispatchInfo.Throw()
   at System.Runtime.CompilerServices.TaskAwaiter.HandleNonSuccessAndDebuggerNotification(Task task)
   at System.Data.Entity.Core.Objects.ObjectContext.<SaveChangesInternalAsync>d__31.MoveNext()
   --- End of inner exception stack trace ---
   at System.Runtime.ExceptionServices.ExceptionDispatchInfo.Throw()
   at System.Runtime.CompilerServices.TaskAwaiter.HandleNonSuccessAndDebuggerNotification(Task task)
   at System.Runtime.CompilerServices.TaskAwaiter`1.GetResult()
   at EventManagement.BusinessLogic.Business.Speakers.<AddUpdateSpeakers_>d__3.MoveNext() in D:\Techxcape Projects\Galactic\CMS\EventManagementPortal\EventManagement.BusinessLogic\Business\Speakers.cs:line 85
--- End of stack trace from previous location where exception was thrown ---
   at System.Runtime.ExceptionServices.ExceptionDispatchInfo.Throw()
   at System.Runtime.CompilerServices.TaskAwaiter.HandleNonSuccessAndDebuggerNotification(Task task)
   at System.Runtime.CompilerServices.TaskAwaiter`1.GetResult()
   at EventManagement.Controllers.SpeakersController.<Create>d__5.MoveNext() in D:\Techxcape Projects\Galactic\CMS\EventManagementPortal\EventManagement\Controllers\SpeakersController.cs:line 70
2018-12-12 19:03:29,227 ERROR [91] CommonHelpers.Helpers.LogError - Speaker Error
System.Data.Entity.Infrastructure.DbUpdateException: An error occurred while updating the entries. See the inner exception for details. ---> System.Data.Entity.Core.UpdateException: An error occurred while updating the entries. See the inner exception for details. ---> System.Data.SqlClient.SqlException: The INSERT statement conflicted with the FOREIGN KEY constraint "FK_EventIDD". The conflict occurred in database "Event_Management2", table "dbo.Event", column 'ID'.
The statement has been terminated.
   at System.Data.SqlClient.SqlCommand.<>c.<ExecuteDbDataReaderAsync>b__180_0(Task`1 result)
   at System.Threading.Tasks.ContinuationResultTaskFromResultTask`2.InnerInvoke()
   at System.Threading.Tasks.Task.Execute()
--- End of stack trace from previous location where exception was thrown ---
   at System.Runtime.ExceptionServices.ExceptionDispatchInfo.Throw()
   at System.Runtime.CompilerServices.TaskAwaiter.HandleNonSuccessAndDebuggerNotification(Task task)
   at System.Data.Entity.Core.Mapping.Update.Internal.DynamicUpdateCommand.<ExecuteAsync>d__0.MoveNext()
--- End of stack trace from previous location where exception was thrown ---
   at System.Runtime.ExceptionServices.ExceptionDispatchInfo.Throw()
   at System.Runtime.CompilerServices.TaskAwaiter.HandleNonSuccessAndDebuggerNotification(Task task)
   at System.Data.Entity.Core.Mapping.Update.Internal.UpdateTranslator.<UpdateAsync>d__0.MoveNext()
   --- End of inner exception stack trace ---
   at System.Data.Entity.Core.Mapping.Update.Internal.UpdateTranslator.<UpdateAsync>d__0.MoveNext()
--- End of stack trace from previous location where exception was thrown ---
   at System.Runtime.ExceptionServices.ExceptionDispatchInfo.Throw()
   at System.Runtime.CompilerServices.TaskAwaiter.HandleNonSuccessAndDebuggerNotification(Task task)
   at System.Data.Entity.Core.Objects.ObjectContext.<ExecuteInTransactionAsync>d__3d`1.MoveNext()
--- End of stack trace from previous location where exception was thrown ---
   at System.Runtime.ExceptionServices.ExceptionDispatchInfo.Throw()
   at System.Runtime.CompilerServices.TaskAwaiter.HandleNonSuccessAndDebuggerNotification(Task task)
   at System.Data.Entity.Core.Objects.ObjectContext.<SaveChangesToStoreAsync>d__39.MoveNext()
--- End of stack trace from previous location where exception was thrown ---
   at System.Runtime.ExceptionServices.ExceptionDispatchInfo.Throw()
   at System.Runtime.CompilerServices.TaskAwaiter.HandleNonSuccessAndDebuggerNotification(Task task)
   at System.Data.Entity.SqlServer.DefaultSqlExecutionStrategy.<ExecuteAsyncImplementation>d__9`1.MoveNext()
--- End of stack trace from previous location where exception was thrown ---
   at System.Runtime.ExceptionServices.ExceptionDispatchInfo.Throw()
   at System.Runtime.CompilerServices.TaskAwaiter.HandleNonSuccessAndDebuggerNotification(Task task)
   at System.Data.Entity.Core.Objects.ObjectContext.<SaveChangesInternalAsync>d__31.MoveNext()
   --- End of inner exception stack trace ---
   at System.Runtime.ExceptionServices.ExceptionDispatchInfo.Throw()
   at System.Runtime.CompilerServices.TaskAwaiter.HandleNonSuccessAndDebuggerNotification(Task task)
   at System.Runtime.CompilerServices.TaskAwaiter`1.GetResult()
   at EventManagement.BusinessLogic.Business.Speakers.<AddUpdateSpeakers_>d__3.MoveNext() in D:\Techxcape Projects\Galactic\CMS\EventManagementPortal\EventManagement.BusinessLogic\Business\Speakers.cs:line 85
--- End of stack trace from previous location where exception was thrown ---
   at System.Runtime.ExceptionServices.ExceptionDispatchInfo.Throw()
   at System.Runtime.CompilerServices.TaskAwaiter.HandleNonSuccessAndDebuggerNotification(Task task)
   at System.Runtime.CompilerServices.TaskAwaiter`1.GetResult()
   at EventManagement.Controllers.SpeakersController.<Create>d__5.MoveNext() in D:\Techxcape Projects\Galactic\CMS\EventManagementPortal\EventManagement\Controllers\SpeakersController.cs:line 70
2018-12-12 20:09:43,270 ERROR [37] CommonHelpers.Helpers.LogError - API Error: 
System.InvalidOperationException: A circular reference was detected while serializing an object of type 'EventManagement.DataAccess.DataBase.Model.AttendesEvent'.
   at System.Web.Script.Serialization.JavaScriptSerializer.SerializeValueInternal(Object o, StringBuilder sb, Int32 depth, Hashtable objectsInUse, SerializationFormat serializationFormat, MemberInfo currentMember)
   at System.Web.Script.Serialization.JavaScriptSerializer.SerializeValue(Object o, StringBuilder sb, Int32 depth, Hashtable objectsInUse, SerializationFormat serializationFormat, MemberInfo currentMember)
   at System.Web.Script.Serialization.JavaScriptSerializer.SerializeEnumerable(IEnumerable enumerable, StringBuilder sb, Int32 depth, Hashtable objectsInUse, SerializationFormat serializationFormat)
   at System.Web.Script.Serialization.JavaScriptSerializer.SerializeValueInternal(Object o, StringBuilder sb, Int32 depth, Hashtable objectsInUse, SerializationFormat serializationFormat, MemberInfo currentMember)
   at System.Web.Script.Serialization.JavaScriptSerializer.SerializeValue(Object o, StringBuilder sb, Int32 depth, Hashtable objectsInUse, SerializationFormat serializationFormat, MemberInfo currentMember)
   at System.Web.Script.Serialization.JavaScriptSerializer.SerializeCustomObject(Object o, StringBuilder sb, Int32 depth, Hashtable objectsInUse, SerializationFormat serializationFormat)
   at System.Web.Script.Serialization.JavaScriptSerializer.SerializeValueInternal(Object o, StringBuilder sb, Int32 depth, Hashtable objectsInUse, SerializationFormat serializationFormat, MemberInfo currentMember)
   at System.Web.Script.Serialization.JavaScriptSerializer.SerializeValue(Object o, StringBuilder sb, Int32 depth, Hashtable objectsInUse, SerializationFormat serializationFormat, MemberInfo currentMember)
   at System.Web.Script.Serialization.JavaScriptSerializer.SerializeCustomObject(Object o, StringBuilder sb, Int32 depth, Hashtable objectsInUse, SerializationFormat serializationFormat)
   at System.Web.Script.Serialization.JavaScriptSerializer.SerializeValueInternal(Object o, StringBuilder sb, Int32 depth, Hashtable objectsInUse, SerializationFormat serializationFormat, MemberInfo currentMember)
   at System.Web.Script.Serialization.JavaScriptSerializer.SerializeValue(Object o, StringBuilder sb, Int32 depth, Hashtable objectsInUse, SerializationFormat serializationFormat, MemberInfo currentMember)
   at System.Web.Script.Serialization.JavaScriptSerializer.SerializeEnumerable(IEnumerable enumerable, StringBuilder sb, Int32 depth, Hashtable objectsInUse, SerializationFormat serializationFormat)
   at System.Web.Script.Serialization.JavaScriptSerializer.SerializeValueInternal(Object o, StringBuilder sb, Int32 depth, Hashtable objectsInUse, SerializationFormat serializationFormat, MemberInfo currentMember)
   at System.Web.Script.Serialization.JavaScriptSerializer.SerializeValue(Object o, StringBuilder sb, Int32 depth, Hashtable objectsInUse, SerializationFormat serializationFormat, MemberInfo currentMember)
   at System.Web.Script.Serialization.JavaScriptSerializer.SerializeCustomObject(Object o, StringBuilder sb, Int32 depth, Hashtable objectsInUse, SerializationFormat serializationFormat)
   at System.Web.Script.Serialization.JavaScriptSerializer.SerializeValueInternal(Object o, StringBuilder sb, Int32 depth, Hashtable objectsInUse, SerializationFormat serializationFormat, MemberInfo currentMember)
   at System.Web.Script.Serialization.JavaScriptSerializer.SerializeValue(Object o, StringBuilder sb, Int32 depth, Hashtable objectsInUse, SerializationFormat serializationFormat, MemberInfo currentMember)
   at System.Web.Script.Serialization.JavaScriptSerializer.SerializeEnumerable(IEnumerable enumerable, StringBuilder sb, Int32 depth, Hashtable objectsInUse, SerializationFormat serializationFormat)
   at System.Web.Script.Serialization.JavaScriptSerializer.SerializeValueInternal(Object o, StringBuilder sb, Int32 depth, Hashtable objectsInUse, SerializationFormat serializationFormat, MemberInfo currentMember)
   at System.Web.Script.Serialization.JavaScriptSerializer.SerializeValue(Object o, StringBuilder sb, Int32 depth, Hashtable objectsInUse, SerializationFormat serializationFormat, MemberInfo currentMember)
   at System.Web.Script.Serialization.JavaScriptSerializer.SerializeCustomObject(Object o, StringBuilder sb, Int32 depth, Hashtable objectsInUse, SerializationFormat serializationFormat)
   at System.Web.Script.Serialization.JavaScriptSerializer.SerializeValueInternal(Object o, StringBuilder sb, Int32 depth, Hashtable objectsInUse, SerializationFormat serializationFormat, MemberInfo currentMember)
   at System.Web.Script.Serialization.JavaScriptSerializer.SerializeValue(Object o, StringBuilder sb, Int32 depth, Hashtable objectsInUse, SerializationFormat serializationFormat, MemberInfo currentMember)
   at System.Web.Script.Serialization.JavaScriptSerializer.Serialize(Object obj, StringBuilder output, SerializationFormat serializationFormat)
   at System.Web.Script.Serialization.JavaScriptSerializer.Serialize(Object obj, SerializationFormat serializationFormat)
   at System.Web.Mvc.JsonResult.ExecuteResult(ControllerContext context)
   at System.Web.Mvc.ControllerActionInvoker.InvokeActionResultFilterRecursive(IList`1 filters, Int32 filterIndex, ResultExecutingContext preContext, ControllerContext controllerContext, ActionResult actionResult)
   at System.Web.Mvc.ControllerActionInvoker.InvokeActionResultFilterRecursive(IList`1 filters, Int32 filterIndex, ResultExecutingContext preContext, ControllerContext controllerContext, ActionResult actionResult)
   at System.Web.Mvc.ControllerActionInvoker.InvokeActionResultWithFilters(ControllerContext controllerContext, IList`1 filters, ActionResult actionResult)
   at System.Web.Mvc.Async.AsyncControllerActionInvoker.<>c__DisplayClass21.<BeginInvokeAction>b__1e(IAsyncResult asyncResult)
2018-12-12 20:25:31,387 ERROR [52] CommonHelpers.Helpers.LogError - API Error: 
System.NullReferenceException: Object reference not set to an instance of an object.
   at EventManagement.BusinessLogic.Business.AuthLogic.<AttendiLogin>d__13.MoveNext() in D:\Techxcape Projects\Galactic\CMS\EventManagementPortal\EventManagement.BusinessLogic\Business\AuthLogic.cs:line 267
--- End of stack trace from previous location where exception was thrown ---
   at System.Runtime.ExceptionServices.ExceptionDispatchInfo.Throw()
   at System.Runtime.CompilerServices.TaskAwaiter.HandleNonSuccessAndDebuggerNotification(Task task)
   at System.Runtime.CompilerServices.TaskAwaiter`1.GetResult()
   at EventManagement.Areas.API.Controllers.AuthController.<Login>d__1.MoveNext() in D:\Techxcape Projects\Galactic\CMS\EventManagementPortal\EventManagement\Areas\API\Controllers\AuthController.cs:line 22
--- End of stack trace from previous location where exception was thrown ---
   at System.Runtime.ExceptionServices.ExceptionDispatchInfo.Throw()
   at System.Runtime.CompilerServices.TaskAwaiter.HandleNonSuccessAndDebuggerNotification(Task task)
   at System.Web.Mvc.Async.TaskAsyncActionDescriptor.EndExecute(IAsyncResult asyncResult)
   at System.Web.Mvc.Async.AsyncControllerActionInvoker.<>c__DisplayClass37.<BeginInvokeAsynchronousActionMethod>b__36(IAsyncResult asyncResult)
   at System.Web.Mvc.Async.AsyncControllerActionInvoker.EndInvokeActionMethod(IAsyncResult asyncResult)
   at System.Web.Mvc.Async.AsyncControllerActionInvoker.AsyncInvocationWithFilters.<InvokeActionMethodFilterAsynchronouslyRecursive>b__3d()
   at System.Web.Mvc.Async.AsyncControllerActionInvoker.AsyncInvocationWithFilters.<>c__DisplayClass46.<InvokeActionMethodFilterAsynchronouslyRecursive>b__3f()
   at System.Web.Mvc.Async.AsyncControllerActionInvoker.EndInvokeActionMethodWithFilters(IAsyncResult asyncResult)
   at System.Web.Mvc.Async.AsyncControllerActionInvoker.<>c__DisplayClass21.<>c__DisplayClass2b.<BeginInvokeAction>b__1c()
   at System.Web.Mvc.Async.AsyncControllerActionInvoker.<>c__DisplayClass21.<BeginInvokeAction>b__1e(IAsyncResult asyncResult)
2018-12-12 20:27:57,470 ERROR [48] CommonHelpers.Helpers.LogError - API Error: 
System.NullReferenceException: Object reference not set to an instance of an object.
   at EventManagement.BusinessLogic.Business.AuthLogic.<AttendiLogin>d__13.MoveNext() in D:\Techxcape Projects\Galactic\CMS\EventManagementPortal\EventManagement.BusinessLogic\Business\AuthLogic.cs:line 267
--- End of stack trace from previous location where exception was thrown ---
   at System.Runtime.ExceptionServices.ExceptionDispatchInfo.Throw()
   at System.Runtime.CompilerServices.TaskAwaiter.HandleNonSuccessAndDebuggerNotification(Task task)
   at System.Runtime.CompilerServices.TaskAwaiter`1.GetResult()
   at EventManagement.Areas.API.Controllers.AuthController.<Login>d__1.MoveNext() in D:\Techxcape Projects\Galactic\CMS\EventManagementPortal\EventManagement\Areas\API\Controllers\AuthController.cs:line 22
--- End of stack trace from previous location where exception was thrown ---
   at System.Runtime.ExceptionServices.ExceptionDispatchInfo.Throw()
   at System.Runtime.CompilerServices.TaskAwaiter.HandleNonSuccessAndDebuggerNotification(Task task)
   at System.Web.Mvc.Async.TaskAsyncActionDescriptor.EndExecute(IAsyncResult asyncResult)
   at System.Web.Mvc.Async.AsyncControllerActionInvoker.<>c__DisplayClass37.<BeginInvokeAsynchronousActionMethod>b__36(IAsyncResult asyncResult)
   at System.Web.Mvc.Async.AsyncControllerActionInvoker.EndInvokeActionMethod(IAsyncResult asyncResult)
   at System.Web.Mvc.Async.AsyncControllerActionInvoker.AsyncInvocationWithFilters.<InvokeActionMethodFilterAsynchronouslyRecursive>b__3d()
   at System.Web.Mvc.Async.AsyncControllerActionInvoker.AsyncInvocationWithFilters.<>c__DisplayClass46.<InvokeActionMethodFilterAsynchronouslyRecursive>b__3f()
   at System.Web.Mvc.Async.AsyncControllerActionInvoker.EndInvokeActionMethodWithFilters(IAsyncResult asyncResult)
   at System.Web.Mvc.Async.AsyncControllerActionInvoker.<>c__DisplayClass21.<>c__DisplayClass2b.<BeginInvokeAction>b__1c()
   at System.Web.Mvc.Async.AsyncControllerActionInvoker.<>c__DisplayClass21.<BeginInvokeAction>b__1e(IAsyncResult asyncResult)
2018-12-12 20:28:07,095 ERROR [52] CommonHelpers.Helpers.LogError - API Error: 
System.NullReferenceException: Object reference not set to an instance of an object.
   at EventManagement.BusinessLogic.Business.AuthLogic.<AttendiLogin>d__13.MoveNext() in D:\Techxcape Projects\Galactic\CMS\EventManagementPortal\EventManagement.BusinessLogic\Business\AuthLogic.cs:line 267
--- End of stack trace from previous location where exception was thrown ---
   at System.Runtime.ExceptionServices.ExceptionDispatchInfo.Throw()
   at System.Runtime.CompilerServices.TaskAwaiter.HandleNonSuccessAndDebuggerNotification(Task task)
   at System.Runtime.CompilerServices.TaskAwaiter`1.GetResult()
   at EventManagement.Areas.API.Controllers.AuthController.<Login>d__1.MoveNext() in D:\Techxcape Projects\Galactic\CMS\EventManagementPortal\EventManagement\Areas\API\Controllers\AuthController.cs:line 22
--- End of stack trace from previous location where exception was thrown ---
   at System.Runtime.ExceptionServices.ExceptionDispatchInfo.Throw()
   at System.Runtime.CompilerServices.TaskAwaiter.HandleNonSuccessAndDebuggerNotification(Task task)
   at System.Web.Mvc.Async.TaskAsyncActionDescriptor.EndExecute(IAsyncResult asyncResult)
   at System.Web.Mvc.Async.AsyncControllerActionInvoker.<>c__DisplayClass37.<BeginInvokeAsynchronousActionMethod>b__36(IAsyncResult asyncResult)
   at System.Web.Mvc.Async.AsyncControllerActionInvoker.EndInvokeActionMethod(IAsyncResult asyncResult)
   at System.Web.Mvc.Async.AsyncControllerActionInvoker.AsyncInvocationWithFilters.<InvokeActionMethodFilterAsynchronouslyRecursive>b__3d()
   at System.Web.Mvc.Async.AsyncControllerActionInvoker.AsyncInvocationWithFilters.<>c__DisplayClass46.<InvokeActionMethodFilterAsynchronouslyRecursive>b__3f()
   at System.Web.Mvc.Async.AsyncControllerActionInvoker.EndInvokeActionMethodWithFilters(IAsyncResult asyncResult)
   at System.Web.Mvc.Async.AsyncControllerActionInvoker.<>c__DisplayClass21.<>c__DisplayClass2b.<BeginInvokeAction>b__1c()
   at System.Web.Mvc.Async.AsyncControllerActionInvoker.<>c__DisplayClass21.<BeginInvokeAction>b__1e(IAsyncResult asyncResult)
2018-12-12 20:28:38,040 ERROR [52] CommonHelpers.Helpers.LogError - API Error: 
System.NullReferenceException: Object reference not set to an instance of an object.
   at EventManagement.BusinessLogic.Business.AuthLogic.<AttendiLogin>d__13.MoveNext() in D:\Techxcape Projects\Galactic\CMS\EventManagementPortal\EventManagement.BusinessLogic\Business\AuthLogic.cs:line 267
--- End of stack trace from previous location where exception was thrown ---
   at System.Runtime.ExceptionServices.ExceptionDispatchInfo.Throw()
   at System.Runtime.CompilerServices.TaskAwaiter.HandleNonSuccessAndDebuggerNotification(Task task)
   at System.Runtime.CompilerServices.TaskAwaiter`1.GetResult()
   at EventManagement.Areas.API.Controllers.AuthController.<Login>d__1.MoveNext() in D:\Techxcape Projects\Galactic\CMS\EventManagementPortal\EventManagement\Areas\API\Controllers\AuthController.cs:line 22
--- End of stack trace from previous location where exception was thrown ---
   at System.Runtime.ExceptionServices.ExceptionDispatchInfo.Throw()
   at System.Runtime.CompilerServices.TaskAwaiter.HandleNonSuccessAndDebuggerNotification(Task task)
   at System.Web.Mvc.Async.TaskAsyncActionDescriptor.EndExecute(IAsyncResult asyncResult)
   at System.Web.Mvc.Async.AsyncControllerActionInvoker.<>c__DisplayClass37.<BeginInvokeAsynchronousActionMethod>b__36(IAsyncResult asyncResult)
   at System.Web.Mvc.Async.AsyncControllerActionInvoker.EndInvokeActionMethod(IAsyncResult asyncResult)
   at System.Web.Mvc.Async.AsyncControllerActionInvoker.AsyncInvocationWithFilters.<InvokeActionMethodFilterAsynchronouslyRecursive>b__3d()
   at System.Web.Mvc.Async.AsyncControllerActionInvoker.AsyncInvocationWithFilters.<>c__DisplayClass46.<InvokeActionMethodFilterAsynchronouslyRecursive>b__3f()
   at System.Web.Mvc.Async.AsyncControllerActionInvoker.EndInvokeActionMethodWithFilters(IAsyncResult asyncResult)
   at System.Web.Mvc.Async.AsyncControllerActionInvoker.<>c__DisplayClass21.<>c__DisplayClass2b.<BeginInvokeAction>b__1c()
   at System.Web.Mvc.Async.AsyncControllerActionInvoker.<>c__DisplayClass21.<BeginInvokeAction>b__1e(IAsyncResult asyncResult)
2018-12-12 20:29:21,749 ERROR [52] CommonHelpers.Helpers.LogError - API Error: 
System.NullReferenceException: Object reference not set to an instance of an object.
   at EventManagement.BusinessLogic.Business.AuthLogic.<AttendiLogin>d__13.MoveNext() in D:\Techxcape Projects\Galactic\CMS\EventManagementPortal\EventManagement.BusinessLogic\Business\AuthLogic.cs:line 267
--- End of stack trace from previous location where exception was thrown ---
   at System.Runtime.ExceptionServices.ExceptionDispatchInfo.Throw()
   at System.Runtime.CompilerServices.TaskAwaiter.HandleNonSuccessAndDebuggerNotification(Task task)
   at System.Runtime.CompilerServices.TaskAwaiter`1.GetResult()
   at EventManagement.Areas.API.Controllers.AuthController.<Login>d__1.MoveNext() in D:\Techxcape Projects\Galactic\CMS\EventManagementPortal\EventManagement\Areas\API\Controllers\AuthController.cs:line 22
--- End of stack trace from previous location where exception was thrown ---
   at System.Runtime.ExceptionServices.ExceptionDispatchInfo.Throw()
   at System.Runtime.CompilerServices.TaskAwaiter.HandleNonSuccessAndDebuggerNotification(Task task)
   at System.Web.Mvc.Async.TaskAsyncActionDescriptor.EndExecute(IAsyncResult asyncResult)
   at System.Web.Mvc.Async.AsyncControllerActionInvoker.<>c__DisplayClass37.<BeginInvokeAsynchronousActionMethod>b__36(IAsyncResult asyncResult)
   at System.Web.Mvc.Async.AsyncControllerActionInvoker.EndInvokeActionMethod(IAsyncResult asyncResult)
   at System.Web.Mvc.Async.AsyncControllerActionInvoker.AsyncInvocationWithFilters.<InvokeActionMethodFilterAsynchronouslyRecursive>b__3d()
   at System.Web.Mvc.Async.AsyncControllerActionInvoker.AsyncInvocationWithFilters.<>c__DisplayClass46.<InvokeActionMethodFilterAsynchronouslyRecursive>b__3f()
   at System.Web.Mvc.Async.AsyncControllerActionInvoker.EndInvokeActionMethodWithFilters(IAsyncResult asyncResult)
   at System.Web.Mvc.Async.AsyncControllerActionInvoker.<>c__DisplayClass21.<>c__DisplayClass2b.<BeginInvokeAction>b__1c()
   at System.Web.Mvc.Async.AsyncControllerActionInvoker.<>c__DisplayClass21.<BeginInvokeAction>b__1e(IAsyncResult asyncResult)
2018-12-12 20:30:16,400 ERROR [31] CommonHelpers.Helpers.LogError - API Error: 
System.NullReferenceException: Object reference not set to an instance of an object.
   at EventManagement.BusinessLogic.Business.AuthLogic.<AttendiLogin>d__13.MoveNext() in D:\Techxcape Projects\Galactic\CMS\EventManagementPortal\EventManagement.BusinessLogic\Business\AuthLogic.cs:line 267
--- End of stack trace from previous location where exception was thrown ---
   at System.Runtime.ExceptionServices.ExceptionDispatchInfo.Throw()
   at System.Runtime.CompilerServices.TaskAwaiter.HandleNonSuccessAndDebuggerNotification(Task task)
   at System.Runtime.CompilerServices.TaskAwaiter`1.GetResult()
   at EventManagement.Areas.API.Controllers.AuthController.<Login>d__1.MoveNext() in D:\Techxcape Projects\Galactic\CMS\EventManagementPortal\EventManagement\Areas\API\Controllers\AuthController.cs:line 22
--- End of stack trace from previous location where exception was thrown ---
   at System.Runtime.ExceptionServices.ExceptionDispatchInfo.Throw()
   at System.Runtime.CompilerServices.TaskAwaiter.HandleNonSuccessAndDebuggerNotification(Task task)
   at System.Web.Mvc.Async.TaskAsyncActionDescriptor.EndExecute(IAsyncResult asyncResult)
   at System.Web.Mvc.Async.AsyncControllerActionInvoker.<>c__DisplayClass37.<BeginInvokeAsynchronousActionMethod>b__36(IAsyncResult asyncResult)
   at System.Web.Mvc.Async.AsyncControllerActionInvoker.EndInvokeActionMethod(IAsyncResult asyncResult)
   at System.Web.Mvc.Async.AsyncControllerActionInvoker.AsyncInvocationWithFilters.<InvokeActionMethodFilterAsynchronouslyRecursive>b__3d()
   at System.Web.Mvc.Async.AsyncControllerActionInvoker.AsyncInvocationWithFilters.<>c__DisplayClass46.<InvokeActionMethodFilterAsynchronouslyRecursive>b__3f()
   at System.Web.Mvc.Async.AsyncControllerActionInvoker.EndInvokeActionMethodWithFilters(IAsyncResult asyncResult)
   at System.Web.Mvc.Async.AsyncControllerActionInvoker.<>c__DisplayClass21.<>c__DisplayClass2b.<BeginInvokeAction>b__1c()
   at System.Web.Mvc.Async.AsyncControllerActionInvoker.<>c__DisplayClass21.<BeginInvokeAction>b__1e(IAsyncResult asyncResult)
2018-12-12 20:31:58,747 ERROR [56] CommonHelpers.Helpers.LogError - API Error: 
System.NullReferenceException: Object reference not set to an instance of an object.
   at EventManagement.BusinessLogic.Business.AuthLogic.<AttendiLogin>d__13.MoveNext() in D:\Techxcape Projects\Galactic\CMS\EventManagementPortal\EventManagement.BusinessLogic\Business\AuthLogic.cs:line 267
--- End of stack trace from previous location where exception was thrown ---
   at System.Runtime.ExceptionServices.ExceptionDispatchInfo.Throw()
   at System.Runtime.CompilerServices.TaskAwaiter.HandleNonSuccessAndDebuggerNotification(Task task)
   at System.Runtime.CompilerServices.TaskAwaiter`1.GetResult()
   at EventManagement.Areas.API.Controllers.AuthController.<Login>d__1.MoveNext() in D:\Techxcape Projects\Galactic\CMS\EventManagementPortal\EventManagement\Areas\API\Controllers\AuthController.cs:line 22
--- End of stack trace from previous location where exception was thrown ---
   at System.Runtime.ExceptionServices.ExceptionDispatchInfo.Throw()
   at System.Runtime.CompilerServices.TaskAwaiter.HandleNonSuccessAndDebuggerNotification(Task task)
   at System.Web.Mvc.Async.TaskAsyncActionDescriptor.EndExecute(IAsyncResult asyncResult)
   at System.Web.Mvc.Async.AsyncControllerActionInvoker.<>c__DisplayClass37.<BeginInvokeAsynchronousActionMethod>b__36(IAsyncResult asyncResult)
   at System.Web.Mvc.Async.AsyncControllerActionInvoker.EndInvokeActionMethod(IAsyncResult asyncResult)
   at System.Web.Mvc.Async.AsyncControllerActionInvoker.AsyncInvocationWithFilters.<InvokeActionMethodFilterAsynchronouslyRecursive>b__3d()
   at System.Web.Mvc.Async.AsyncControllerActionInvoker.AsyncInvocationWithFilters.<>c__DisplayClass46.<InvokeActionMethodFilterAsynchronouslyRecursive>b__3f()
   at System.Web.Mvc.Async.AsyncControllerActionInvoker.EndInvokeActionMethodWithFilters(IAsyncResult asyncResult)
   at System.Web.Mvc.Async.AsyncControllerActionInvoker.<>c__DisplayClass21.<>c__DisplayClass2b.<BeginInvokeAction>b__1c()
   at System.Web.Mvc.Async.AsyncControllerActionInvoker.<>c__DisplayClass21.<BeginInvokeAction>b__1e(IAsyncResult asyncResult)
2018-12-12 20:39:52,525 ERROR [48] CommonHelpers.Helpers.LogError - API Error: 
System.NullReferenceException: Object reference not set to an instance of an object.
   at EventManagement.BusinessLogic.Business.AuthLogic.<AttendiLogin>d__13.MoveNext() in D:\Techxcape Projects\Galactic\CMS\EventManagementPortal\EventManagement.BusinessLogic\Business\AuthLogic.cs:line 267
--- End of stack trace from previous location where exception was thrown ---
   at System.Runtime.ExceptionServices.ExceptionDispatchInfo.Throw()
   at System.Runtime.CompilerServices.TaskAwaiter.HandleNonSuccessAndDebuggerNotification(Task task)
   at System.Runtime.CompilerServices.TaskAwaiter`1.GetResult()
   at EventManagement.Areas.API.Controllers.AuthController.<Login>d__1.MoveNext() in D:\Techxcape Projects\Galactic\CMS\EventManagementPortal\EventManagement\Areas\API\Controllers\AuthController.cs:line 22
--- End of stack trace from previous location where exception was thrown ---
   at System.Runtime.ExceptionServices.ExceptionDispatchInfo.Throw()
   at System.Runtime.CompilerServices.TaskAwaiter.HandleNonSuccessAndDebuggerNotification(Task task)
   at System.Web.Mvc.Async.TaskAsyncActionDescriptor.EndExecute(IAsyncResult asyncResult)
   at System.Web.Mvc.Async.AsyncControllerActionInvoker.<>c__DisplayClass37.<BeginInvokeAsynchronousActionMethod>b__36(IAsyncResult asyncResult)
   at System.Web.Mvc.Async.AsyncControllerActionInvoker.EndInvokeActionMethod(IAsyncResult asyncResult)
   at System.Web.Mvc.Async.AsyncControllerActionInvoker.AsyncInvocationWithFilters.<InvokeActionMethodFilterAsynchronouslyRecursive>b__3d()
   at System.Web.Mvc.Async.AsyncControllerActionInvoker.AsyncInvocationWithFilters.<>c__DisplayClass46.<InvokeActionMethodFilterAsynchronouslyRecursive>b__3f()
   at System.Web.Mvc.Async.AsyncControllerActionInvoker.EndInvokeActionMethodWithFilters(IAsyncResult asyncResult)
   at System.Web.Mvc.Async.AsyncControllerActionInvoker.<>c__DisplayClass21.<>c__DisplayClass2b.<BeginInvokeAction>b__1c()
   at System.Web.Mvc.Async.AsyncControllerActionInvoker.<>c__DisplayClass21.<BeginInvokeAction>b__1e(IAsyncResult asyncResult)
2018-12-12 20:41:50,122 ERROR [28] CommonHelpers.Helpers.LogError - API Error: 
System.ArgumentException: The parameters dictionary contains a null entry for parameter 'type' of non-nullable type 'System.Int32' for method 'System.Threading.Tasks.Task`1[System.Web.Mvc.ActionResult] Login(System.String, System.String, Int32, System.String, System.String)' in 'EventManagement.Areas.API.Controllers.AuthController'. An optional parameter must be a reference type, a nullable type, or be declared as an optional parameter.
Parameter name: parameters
   at System.Web.Mvc.ActionDescriptor.ExtractParameterFromDictionary(ParameterInfo parameterInfo, IDictionary`2 parameters, MethodInfo methodInfo)
   at System.Linq.Enumerable.WhereSelectArrayIterator`2.MoveNext()
   at System.Linq.Buffer`1..ctor(IEnumerable`1 source)
   at System.Linq.Enumerable.ToArray[TSource](IEnumerable`1 source)
   at System.Web.Mvc.Async.TaskAsyncActionDescriptor.BeginExecute(ControllerContext controllerContext, IDictionary`2 parameters, AsyncCallback callback, Object state)
   at System.Web.Mvc.Async.AsyncControllerActionInvoker.<>c__DisplayClass37.<BeginInvokeAsynchronousActionMethod>b__35(AsyncCallback asyncCallback, Object asyncState)
   at System.Web.Mvc.Async.AsyncResultWrapper.WrappedAsyncResultBase`1.Begin(AsyncCallback callback, Object state, Int32 timeout)
   at System.Web.Mvc.Async.AsyncControllerActionInvoker.BeginInvokeAsynchronousActionMethod(ControllerContext controllerContext, AsyncActionDescriptor actionDescriptor, IDictionary`2 parameters, AsyncCallback callback, Object state)
   at System.Web.Mvc.Async.AsyncControllerActionInvoker.AsyncInvocationWithFilters.InvokeActionMethodFilterAsynchronouslyRecursive(Int32 filterIndex)
   at System.Web.Mvc.Async.AsyncControllerActionInvoker.AsyncInvocationWithFilters.InvokeActionMethodFilterAsynchronouslyRecursive(Int32 filterIndex)
   at System.Web.Mvc.Async.AsyncControllerActionInvoker.<>c__DisplayClass33.<BeginInvokeActionMethodWithFilters>b__31(AsyncCallback asyncCallback, Object asyncState)
   at System.Web.Mvc.Async.AsyncResultWrapper.WrappedAsyncResultBase`1.Begin(AsyncCallback callback, Object state, Int32 timeout)
   at System.Web.Mvc.Async.AsyncControllerActionInvoker.BeginInvokeActionMethodWithFilters(ControllerContext controllerContext, IList`1 filters, ActionDescriptor actionDescriptor, IDictionary`2 parameters, AsyncCallback callback, Object state)
   at System.Web.Mvc.Async.AsyncControllerActionInvoker.<>c__DisplayClass21.<BeginInvokeAction>b__19(AsyncCallback asyncCallback, Object asyncState)
2018-12-12 20:42:38,175 ERROR [33] CommonHelpers.Helpers.LogError - API Error: 
System.NullReferenceException: Object reference not set to an instance of an object.
   at EventManagement.BusinessLogic.Business.AuthLogic.<AttendiLogin>d__13.MoveNext() in D:\Techxcape Projects\Galactic\CMS\EventManagementPortal\EventManagement.BusinessLogic\Business\AuthLogic.cs:line 267
--- End of stack trace from previous location where exception was thrown ---
   at System.Runtime.ExceptionServices.ExceptionDispatchInfo.Throw()
   at System.Runtime.CompilerServices.TaskAwaiter.HandleNonSuccessAndDebuggerNotification(Task task)
   at System.Runtime.CompilerServices.TaskAwaiter`1.GetResult()
   at EventManagement.Areas.API.Controllers.AuthController.<Login>d__1.MoveNext() in D:\Techxcape Projects\Galactic\CMS\EventManagementPortal\EventManagement\Areas\API\Controllers\AuthController.cs:line 22
--- End of stack trace from previous location where exception was thrown ---
   at System.Runtime.ExceptionServices.ExceptionDispatchInfo.Throw()
   at System.Runtime.CompilerServices.TaskAwaiter.HandleNonSuccessAndDebuggerNotification(Task task)
   at System.Web.Mvc.Async.TaskAsyncActionDescriptor.EndExecute(IAsyncResult asyncResult)
   at System.Web.Mvc.Async.AsyncControllerActionInvoker.<>c__DisplayClass37.<BeginInvokeAsynchronousActionMethod>b__36(IAsyncResult asyncResult)
   at System.Web.Mvc.Async.AsyncControllerActionInvoker.EndInvokeActionMethod(IAsyncResult asyncResult)
   at System.Web.Mvc.Async.AsyncControllerActionInvoker.AsyncInvocationWithFilters.<InvokeActionMethodFilterAsynchronouslyRecursive>b__3d()
   at System.Web.Mvc.Async.AsyncControllerActionInvoker.AsyncInvocationWithFilters.<>c__DisplayClass46.<InvokeActionMethodFilterAsynchronouslyRecursive>b__3f()
   at System.Web.Mvc.Async.AsyncControllerActionInvoker.EndInvokeActionMethodWithFilters(IAsyncResult asyncResult)
   at System.Web.Mvc.Async.AsyncControllerActionInvoker.<>c__DisplayClass21.<>c__DisplayClass2b.<BeginInvokeAction>b__1c()
   at System.Web.Mvc.Async.AsyncControllerActionInvoker.<>c__DisplayClass21.<BeginInvokeAction>b__1e(IAsyncResult asyncResult)
2018-12-12 20:43:03,463 ERROR [33] CommonHelpers.Helpers.LogError - API Error: 
System.NullReferenceException: Object reference not set to an instance of an object.
   at EventManagement.BusinessLogic.Business.AuthLogic.<AttendiLogin>d__13.MoveNext() in D:\Techxcape Projects\Galactic\CMS\EventManagementPortal\EventManagement.BusinessLogic\Business\AuthLogic.cs:line 267
--- End of stack trace from previous location where exception was thrown ---
   at System.Runtime.ExceptionServices.ExceptionDispatchInfo.Throw()
   at System.Runtime.CompilerServices.TaskAwaiter.HandleNonSuccessAndDebuggerNotification(Task task)
   at System.Runtime.CompilerServices.TaskAwaiter`1.GetResult()
   at EventManagement.Areas.API.Controllers.AuthController.<Login>d__1.MoveNext() in D:\Techxcape Projects\Galactic\CMS\EventManagementPortal\EventManagement\Areas\API\Controllers\AuthController.cs:line 22
--- End of stack trace from previous location where exception was thrown ---
   at System.Runtime.ExceptionServices.ExceptionDispatchInfo.Throw()
   at System.Runtime.CompilerServices.TaskAwaiter.HandleNonSuccessAndDebuggerNotification(Task task)
   at System.Web.Mvc.Async.TaskAsyncActionDescriptor.EndExecute(IAsyncResult asyncResult)
   at System.Web.Mvc.Async.AsyncControllerActionInvoker.<>c__DisplayClass37.<BeginInvokeAsynchronousActionMethod>b__36(IAsyncResult asyncResult)
   at System.Web.Mvc.Async.AsyncControllerActionInvoker.EndInvokeActionMethod(IAsyncResult asyncResult)
   at System.Web.Mvc.Async.AsyncControllerActionInvoker.AsyncInvocationWithFilters.<InvokeActionMethodFilterAsynchronouslyRecursive>b__3d()
   at System.Web.Mvc.Async.AsyncControllerActionInvoker.AsyncInvocationWithFilters.<>c__DisplayClass46.<InvokeActionMethodFilterAsynchronouslyRecursive>b__3f()
   at System.Web.Mvc.Async.AsyncControllerActionInvoker.EndInvokeActionMethodWithFilters(IAsyncResult asyncResult)
   at System.Web.Mvc.Async.AsyncControllerActionInvoker.<>c__DisplayClass21.<>c__DisplayClass2b.<BeginInvokeAction>b__1c()
   at System.Web.Mvc.Async.AsyncControllerActionInvoker.<>c__DisplayClass21.<BeginInvokeAction>b__1e(IAsyncResult asyncResult)
2018-12-12 20:48:35,277 ERROR [57] CommonHelpers.Helpers.LogError - API Error: 
System.NullReferenceException: Object reference not set to an instance of an object.
   at EventManagement.BusinessLogic.Business.AuthLogic.<AttendiLogin>d__13.MoveNext() in D:\Techxcape Projects\Galactic\CMS\EventManagementPortal\EventManagement.BusinessLogic\Business\AuthLogic.cs:line 267
--- End of stack trace from previous location where exception was thrown ---
   at System.Runtime.ExceptionServices.ExceptionDispatchInfo.Throw()
   at System.Runtime.CompilerServices.TaskAwaiter.HandleNonSuccessAndDebuggerNotification(Task task)
   at System.Runtime.CompilerServices.TaskAwaiter`1.GetResult()
   at EventManagement.Areas.API.Controllers.AuthController.<Login>d__1.MoveNext() in D:\Techxcape Projects\Galactic\CMS\EventManagementPortal\EventManagement\Areas\API\Controllers\AuthController.cs:line 22
--- End of stack trace from previous location where exception was thrown ---
   at System.Runtime.ExceptionServices.ExceptionDispatchInfo.Throw()
   at System.Runtime.CompilerServices.TaskAwaiter.HandleNonSuccessAndDebuggerNotification(Task task)
   at System.Web.Mvc.Async.TaskAsyncActionDescriptor.EndExecute(IAsyncResult asyncResult)
   at System.Web.Mvc.Async.AsyncControllerActionInvoker.<>c__DisplayClass37.<BeginInvokeAsynchronousActionMethod>b__36(IAsyncResult asyncResult)
   at System.Web.Mvc.Async.AsyncControllerActionInvoker.EndInvokeActionMethod(IAsyncResult asyncResult)
   at System.Web.Mvc.Async.AsyncControllerActionInvoker.AsyncInvocationWithFilters.<InvokeActionMethodFilterAsynchronouslyRecursive>b__3d()
   at System.Web.Mvc.Async.AsyncControllerActionInvoker.AsyncInvocationWithFilters.<>c__DisplayClass46.<InvokeActionMethodFilterAsynchronouslyRecursive>b__3f()
   at System.Web.Mvc.Async.AsyncControllerActionInvoker.EndInvokeActionMethodWithFilters(IAsyncResult asyncResult)
   at System.Web.Mvc.Async.AsyncControllerActionInvoker.<>c__DisplayClass21.<>c__DisplayClass2b.<BeginInvokeAction>b__1c()
   at System.Web.Mvc.Async.AsyncControllerActionInvoker.<>c__DisplayClass21.<BeginInvokeAction>b__1e(IAsyncResult asyncResult)
2018-12-12 20:49:39,315 ERROR [42] CommonHelpers.Helpers.LogError - API Error: 
System.NullReferenceException: Object reference not set to an instance of an object.
   at EventManagement.BusinessLogic.Business.AuthLogic.<AttendiLogin>d__13.MoveNext() in D:\Techxcape Projects\Galactic\CMS\EventManagementPortal\EventManagement.BusinessLogic\Business\AuthLogic.cs:line 267
--- End of stack trace from previous location where exception was thrown ---
   at System.Runtime.ExceptionServices.ExceptionDispatchInfo.Throw()
   at System.Runtime.CompilerServices.TaskAwaiter.HandleNonSuccessAndDebuggerNotification(Task task)
   at System.Runtime.CompilerServices.TaskAwaiter`1.GetResult()
   at EventManagement.Areas.API.Controllers.AuthController.<Login>d__1.MoveNext() in D:\Techxcape Projects\Galactic\CMS\EventManagementPortal\EventManagement\Areas\API\Controllers\AuthController.cs:line 22
--- End of stack trace from previous location where exception was thrown ---
   at System.Runtime.ExceptionServices.ExceptionDispatchInfo.Throw()
   at System.Runtime.CompilerServices.TaskAwaiter.HandleNonSuccessAndDebuggerNotification(Task task)
   at System.Web.Mvc.Async.TaskAsyncActionDescriptor.EndExecute(IAsyncResult asyncResult)
   at System.Web.Mvc.Async.AsyncControllerActionInvoker.<>c__DisplayClass37.<BeginInvokeAsynchronousActionMethod>b__36(IAsyncResult asyncResult)
   at System.Web.Mvc.Async.AsyncControllerActionInvoker.EndInvokeActionMethod(IAsyncResult asyncResult)
   at System.Web.Mvc.Async.AsyncControllerActionInvoker.AsyncInvocationWithFilters.<InvokeActionMethodFilterAsynchronouslyRecursive>b__3d()
   at System.Web.Mvc.Async.AsyncControllerActionInvoker.AsyncInvocationWithFilters.<>c__DisplayClass46.<InvokeActionMethodFilterAsynchronouslyRecursive>b__3f()
   at System.Web.Mvc.Async.AsyncControllerActionInvoker.EndInvokeActionMethodWithFilters(IAsyncResult asyncResult)
   at System.Web.Mvc.Async.AsyncControllerActionInvoker.<>c__DisplayClass21.<>c__DisplayClass2b.<BeginInvokeAction>b__1c()
   at System.Web.Mvc.Async.AsyncControllerActionInvoker.<>c__DisplayClass21.<BeginInvokeAction>b__1e(IAsyncResult asyncResult)
2018-12-12 20:51:41,720 ERROR [37] CommonHelpers.Helpers.LogError - API Error: 
System.NullReferenceException: Object reference not set to an instance of an object.
   at EventManagement.BusinessLogic.Business.AuthLogic.<AttendiLogin>d__13.MoveNext() in D:\Techxcape Projects\Galactic\CMS\EventManagementPortal\EventManagement.BusinessLogic\Business\AuthLogic.cs:line 267
--- End of stack trace from previous location where exception was thrown ---
   at System.Runtime.ExceptionServices.ExceptionDispatchInfo.Throw()
   at System.Runtime.CompilerServices.TaskAwaiter.HandleNonSuccessAndDebuggerNotification(Task task)
   at System.Runtime.CompilerServices.TaskAwaiter`1.GetResult()
   at EventManagement.Areas.API.Controllers.AuthController.<Login>d__1.MoveNext() in D:\Techxcape Projects\Galactic\CMS\EventManagementPortal\EventManagement\Areas\API\Controllers\AuthController.cs:line 22
--- End of stack trace from previous location where exception was thrown ---
   at System.Runtime.ExceptionServices.ExceptionDispatchInfo.Throw()
   at System.Runtime.CompilerServices.TaskAwaiter.HandleNonSuccessAndDebuggerNotification(Task task)
   at System.Web.Mvc.Async.TaskAsyncActionDescriptor.EndExecute(IAsyncResult asyncResult)
   at System.Web.Mvc.Async.AsyncControllerActionInvoker.<>c__DisplayClass37.<BeginInvokeAsynchronousActionMethod>b__36(IAsyncResult asyncResult)
   at System.Web.Mvc.Async.AsyncControllerActionInvoker.EndInvokeActionMethod(IAsyncResult asyncResult)
   at System.Web.Mvc.Async.AsyncControllerActionInvoker.AsyncInvocationWithFilters.<InvokeActionMethodFilterAsynchronouslyRecursive>b__3d()
   at System.Web.Mvc.Async.AsyncControllerActionInvoker.AsyncInvocationWithFilters.<>c__DisplayClass46.<InvokeActionMethodFilterAsynchronouslyRecursive>b__3f()
   at System.Web.Mvc.Async.AsyncControllerActionInvoker.EndInvokeActionMethodWithFilters(IAsyncResult asyncResult)
   at System.Web.Mvc.Async.AsyncControllerActionInvoker.<>c__DisplayClass21.<>c__DisplayClass2b.<BeginInvokeAction>b__1c()
   at System.Web.Mvc.Async.AsyncControllerActionInvoker.<>c__DisplayClass21.<BeginInvokeAction>b__1e(IAsyncResult asyncResult)
